Workbook
Name SegmentaciónDeDatos_Country: #N/A
Name SegmentaciónDeDatos_Year: #N/A

Sheet Hoja1
H1: Year | I1: All
B3: Mundiales | D3: Recuento de Year | F3: Goles anotados | H3: Miles asistencia
B4: 20 | D4: 852 | F4: 2379 | H4: 3745.7647
F6: Promedio de GoalsScored
B7: Goles anotados por mundial | C7: Suma de GoalsScored | F7: 118.95 | H7: =GETPIVOTDATA("[Measures].[Recuento de Year 2]",$D$3)/GETPIVOTDATA("[Measures].[Promedio de GoalsScored]",$F$6) -> 7.1626734
B8: 1930 | C8: 70
B9: 1934 | C9: 70
B10: 1938 | C10: 84
B11: 1950 | C11: 88 | E11: Asistencia por década | F11: Millones | H11: Etiquetas de fila | I11: Recuento de Year
B12: 1954 | C12: 140 | E12: 1930 | F12: 1.329249 | H12: England | I12: 1
B13: 1958 | C13: 126 | E13: 1950 | F13: 2.633663 | H13: Argentina | I13: 2
B14: 1962 | C14: 89 | E14: 1960 | F14: 2.456307 | H14: Uruguay | I14: 2
B15: 1966 | C15: 89 | E15: 1970 | F15: 5.015519 | H15: España | I15: 2
B16: 1970 | C16: 95 | E16: 1980 | F16: 4.503754 | H16: Alemania | I16: 4
B17: 1974 | C17: 97 | E17: 1990 | F17: 8.888853 | H17: Italia | I17: 4
B18: 1978 | C18: 102 | E18: 2000 | F18: 6.064636 | H18: Brasil | I18: 5
B19: 1982 | C19: 146 | E19: 2010 | F19: 6.565666 | H19: Total general | I19: 20
B20: 1986 | C20: 132 | E20: Total general | F20: 37.457647
B21: 1990 | C21: 115
B22: 1994 | C22: 141
B23: 1998 | C23: 171
B24: 2002 | C24: 161 | E24: Campeones | H24: Etiquetas de fila | I24: Suma de Goles por partido
B25: 2006 | C25: 147 | E25: Argentina | H25: Ronaldo | I25: 17
B26: 2010 | C26: 145 | E26: Brasil | H26: Klose | I26: 17
B27: 2014 | C27: 171 | E27: Alemania | H27: Gerd Mueller | I27: 14
B28: Total general | C28: 2379 | E28: England | H28: Just Fontaine | I28: 13
E29: España | H29: Pelï¿½ (Edson Arantes Do Nascimento) | I29: 12
E30: Italia | H30: Mï¿½Ller | I30: 12
E31: Uruguay | H31: Sandor Kocsis | I31: 11
E32: Total general | H32: Total general | I32: 96
E36: Recuento de Team Name
E37: 82
E40: Campeones | H40: País sede | K40: CAMPEÓN | M40: SUBCAMPEÓN | O40: TERCERO | Q40: Cuarto
E41: 2014 | H41: 2014 | K41: 2014 | M41: 2014 | O41: 2014 | Q41: 2014
E42: Alemania | H42: 2010 | K42: Alemania | M42: Argentina | O42: Netherlands | Q42: Brasil
E43: 2010 | H43: 2006 | K43: 2010 | M43: 2010 | O43: 2010 | Q43: 2010
E44: España | H44: 2002 | K44: España | M44: Netherlands | O44: Alemania | Q44: Uruguay
E45: 2006 | H45: 1998 | K45: 2006 | M45: 2006 | O45: 2006 | Q45: 2006
E46: Italia | H46: 1994 | K46: Italia | M46: Francia | O46: Alemania | Q46: Portugal
E47: 2002 | H47: 1990 | K47: 2002 | M47: 2002 | O47: 2002 | Q47: 2002
...

Sheet General
P7: =GETPIVOTDATA("[Measures].[Recuento de Year]",Hoja1!$B$3) -> 20
P8: =GETPIVOTDATA("[Measures].[Recuento de Year 2]",Hoja1!$D$3) -> 852
P9: =GETPIVOTDATA("[Measures].[Recuento de Team Name]",Hoja1!$E$36) -> 82
P10: =GETPIVOTDATA("[Measures].[Suma de GoalsScored]",Hoja1!$F$3) -> 2379
P11: =GETPIVOTDATA("[Measures].[Miles asistencia]",Hoja1!$H$3) -> 3745.7647
P12: =GETPIVOTDATA("[Measures].[Promedio de GoalsScored]",Hoja1!$F$6) -> 118.95
O14: Selección activa | P14: =Hoja1!K41 -> 2014
O15: Campeón | P15: =Hoja1!K42 -> Alemania
O16: Sub-campeón | P16: =Hoja1!M42 -> Argentina
O17: Tercero | P17: =Hoja1!O42 -> Netherlands
O18: Cuarto | P18: =Hoja1!Q42 -> Brasil
O20: =GETPIVOTDATA("[Measures].[Suma de Goles por partido]",Hoja1!$H$24,"[WorldCupPlayers].[Player Name]","[WorldCupPlayers].[Player Name].&[RONALDO]") -> 17 | P20: =Hoja1!H25 -> Ronaldo
O21: =GETPIVOTDATA("[Measures].[Suma de Goles por partido]",Hoja1!$H$24,"[WorldCupPlayers].[Player Name]","[WorldCupPlayers].[Player Name].&[KLOSE]") -> 17 | P21: =Hoja1!H26 -> Klose
O22: =GETPIVOTDATA("[Measures].[Suma de Goles por partido]",Hoja1!$H$24,"[WorldCupPlayers].[Player Name]","[WorldCupPlayers].[Player Name].&[Gerd MUELLER]") -> 14 | P22: =Hoja1!H27 -> Gerd Mueller
O23: =GETPIVOTDATA("[Measures].[Suma de Goles por partido]",Hoja1!$H$24,"[WorldCupPlayers].[Player Name]","[WorldCupPlayers].[Player Name].&[Just FONTAINE]") -> 13 | P23: =Hoja1!H28 -> Just Fontaine
O24: =GETPIVOTDATA("[Measures].[Suma de Goles por partido]",Hoja1!$H$24,"[WorldCupPlayers].[Player Name]","[WorldCupPlayers].[Player Name].&[PELï¿½ (Edson Arantes do Nascimento)]") -> 12 | P24: =Hoja1!H29 -> Pelï¿½ (Edson Arantes Do Nascimento)
O27: Ultimos campeones
O28: =Hoja1!E50 -> España | P28: =Hoja1!E49 -> 1998
O29: =Hoja1!E48 -> Brasil | P29: =Hoja1!E47 -> 2002
O30: =Hoja1!E46 -> Italia | P30: =Hoja1!E45 -> 2006
O31: =Hoja1!E44 -> España | P31: =Hoja1!E43 -> 2010
O32: =Hoja1!E42 -> Alemania | P32: =Hoja1!E41 -> 2014
